<?xml version="1.0" encoding="UTF-8"?>
<testng-results ignored="0" total="3" passed="1" failed="1" skipped="1">
  <reporter-output>
  </reporter-output>
  <suite started-at="2023-01-05T15:21:35 IST" name="Suite" finished-at="2023-01-05T15:21:35 IST" duration-ms="69">
    <groups>
    </groups>
    <test started-at="2023-01-05T15:21:35 IST" name="Test" finished-at="2023-01-05T15:21:35 IST" duration-ms="69">
      <class name="TestNGTutorial.TestNGTutorial.ClassCallsLiseners">
        <test-method signature="firstTest()[pri:0, instance:TestNGTutorial.TestNGTutorial.ClassCallsLiseners@14dd9eb7]" started-at="2023-01-05T15:21:35 IST" name="firstTest" finished-at="2023-01-05T15:21:35 IST" duration-ms="16" status="PASS">
          <reporter-output>
          </reporter-output>
        </test-method> <!-- firstTest -->
        <test-method signature="secondTest()[pri:0, instance:TestNGTutorial.TestNGTutorial.ClassCallsLiseners@14dd9eb7]" started-at="2023-01-05T15:21:35 IST" name="secondTest" finished-at="2023-01-05T15:21:35 IST" duration-ms="2" status="FAIL">
          <exception class="java.lang.AssertionError">
            <message>
              <![CDATA[expected [true] but found [false]]]>
            </message>
            <full-stacktrace>
              <![CDATA[java.lang.AssertionError: expected [true] but found [false]
at org.testng.Assert.fail(Assert.java:99)
at org.testng.Assert.failNotEquals(Assert.java:1037)
at org.testng.Assert.assertTrue(Assert.java:45)
at org.testng.Assert.assertTrue(Assert.java:55)
at TestNGTutorial.TestNGTutorial.ClassCallsLiseners.secondTest(ClassCallsLiseners.java:19)
at java.base/jdk.internal.reflect.DirectMethodHandleAccessor.invoke(DirectMethodHandleAccessor.java:104)
at java.base/java.lang.reflect.Method.invoke(Method.java:577)
at org.testng.internal.MethodInvocationHelper.invokeMethod(MethodInvocationHelper.java:133)
at org.testng.internal.TestInvoker.invokeMethod(TestInvoker.java:598)
at org.testng.internal.TestInvoker.invokeTestMethod(TestInvoker.java:173)
at org.testng.internal.MethodRunner.runInSequence(MethodRunner.java:46)
at org.testng.internal.TestInvoker$MethodInvocationAgent.invoke(TestInvoker.java:824)
at org.testng.internal.TestInvoker.invokeTestMethods(TestInvoker.java:146)
at org.testng.internal.TestMethodWorker.invokeTestMethods(TestMethodWorker.java:146)
at org.testng.internal.TestMethodWorker.run(TestMethodWorker.java:128)
at java.base/java.util.ArrayList.forEach(ArrayList.java:1511)
at org.testng.TestRunner.privateRun(TestRunner.java:794)
at org.testng.TestRunner.run(TestRunner.java:596)
at org.testng.SuiteRunner.runTest(SuiteRunner.java:377)
at org.testng.SuiteRunner.runSequentially(SuiteRunner.java:371)
at org.testng.SuiteRunner.privateRun(SuiteRunner.java:332)
at org.testng.SuiteRunner.run(SuiteRunner.java:276)
at org.testng.SuiteRunnerWorker.runSuite(SuiteRunnerWorker.java:53)
at org.testng.SuiteRunnerWorker.run(SuiteRunnerWorker.java:96)
at org.testng.TestNG.runSuitesSequentially(TestNG.java:1212)
at org.testng.TestNG.runSuitesLocally(TestNG.java:1134)
at org.testng.TestNG.runSuites(TestNG.java:1063)
at org.testng.TestNG.run(TestNG.java:1031)
at org.testng.remote.AbstractRemoteTestNG.run(AbstractRemoteTestNG.java:115)
at org.testng.remote.RemoteTestNG.initAndRun(RemoteTestNG.java:251)
at org.testng.remote.RemoteTestNG.main(RemoteTestNG.java:77)
]]>
            </full-stacktrace>
          </exception> <!-- java.lang.AssertionError -->
          <reporter-output>
          </reporter-output>
        </test-method> <!-- secondTest -->
        <test-method signature="third()[pri:0, instance:TestNGTutorial.TestNGTutorial.ClassCallsLiseners@14dd9eb7]" started-at="2023-01-05T15:21:35 IST" name="third" finished-at="2023-01-05T15:21:35 IST" depends-on-methods="TestNGTutorial.TestNGTutorial.ClassCallsLiseners.secondTest" duration-ms="0" status="SKIP">
          <exception class="java.lang.Throwable">
            <message>
              <![CDATA[Method ClassCallsLiseners.third()[pri:0, instance:TestNGTutorial.TestNGTutorial.ClassCallsLiseners@14dd9eb7] depends on not successfully finished methods]]>
            </message>
            <full-stacktrace>
              <![CDATA[java.lang.Throwable: Method ClassCallsLiseners.third()[pri:0, instance:TestNGTutorial.TestNGTutorial.ClassCallsLiseners@14dd9eb7] depends on not successfully finished methods
at org.testng.internal.TestInvoker.invokeTestMethods(TestInvoker.java:102)
at org.testng.internal.TestMethodWorker.invokeTestMethods(TestMethodWorker.java:146)
at org.testng.internal.TestMethodWorker.run(TestMethodWorker.java:128)
at java.base/java.util.ArrayList.forEach(ArrayList.java:1511)
at org.testng.TestRunner.privateRun(TestRunner.java:794)
at org.testng.TestRunner.run(TestRunner.java:596)
at org.testng.SuiteRunner.runTest(SuiteRunner.java:377)
at org.testng.SuiteRunner.runSequentially(SuiteRunner.java:371)
at org.testng.SuiteRunner.privateRun(SuiteRunner.java:332)
at org.testng.SuiteRunner.run(SuiteRunner.java:276)
at org.testng.SuiteRunnerWorker.runSuite(SuiteRunnerWorker.java:53)
at org.testng.SuiteRunnerWorker.run(SuiteRunnerWorker.java:96)
at org.testng.TestNG.runSuitesSequentially(TestNG.java:1212)
at org.testng.TestNG.runSuitesLocally(TestNG.java:1134)
at org.testng.TestNG.runSuites(TestNG.java:1063)
at org.testng.TestNG.run(TestNG.java:1031)
at org.testng.remote.AbstractRemoteTestNG.run(AbstractRemoteTestNG.java:115)
at org.testng.remote.RemoteTestNG.initAndRun(RemoteTestNG.java:251)
at org.testng.remote.RemoteTestNG.main(RemoteTestNG.java:77)
]]>
            </full-stacktrace>
          </exception> <!-- java.lang.Throwable -->
          <reporter-output>
          </reporter-output>
        </test-method> <!-- third -->
      </class> <!-- TestNGTutorial.TestNGTutorial.ClassCallsLiseners -->
    </test> <!-- Test -->
  </suite> <!-- Suite -->
</testng-results>
